### 其它

#### resolve

除了通过`new`创建对象,还提供了静态方法`resolve`可以快捷创建一个状态为`Fulfilled`的`promise`对象.(或者理解为语法糖)

```javascript
//常规
new ES6Promise((resolve, reject) => {
  resolve(1);
}).then((value) => {
  console.log(value);
});
// 1

// 快捷方式(语法糖)
ES6Promise.resolve(1).then((value) => {
  console.log(value);
});
//1
```

以上示例演示了通过`new`创建对象与快捷方式的区别,无论哪种方式最后都是返回`promise`对象调用`then`方法,所以我们看静态方法`resolve`的源码内部内部是否创建并返回了`promise`对象.

```javascript
//源码
Promise$1.resolve = resolve$1;

function resolve$1(object) {
  /*jshint validthis:true */
  var Constructor = this;

  if (
    object &&
    typeof object === 'object' &&
    object.constructor === Constructor
  ) {
    return object;
  }

  var promise = new Constructor(noop);
  resolve(promise, object);
  return promise;
}
```

静态方法内做的事情相对还是比较简单的.

- 判断`object`参数类型,如果参数是一个`promise`对象不做任何处理直接返回该对象

```javascript
var p1 = new ES6Promise((resolve, reject) => {
  resolve(1);
});
var p2 = ES6Promise.resolve(p1).then((v) => {
  console.log(v);
});
```

上面的示例演示就是这种情况`p2`通过快捷方式`ES6Promise.resolve(p1)`创建对象时传递的参数为`p1`是`promise`对象,所以构造函数内会直接返回该对象`p1`.

- 通过`new`创建对象,并且内部调用`resolve`函数改变状态为`Fulfilled`
- 最后返回内部创建的`promise`对象

**所以静态方法内部是帮我们创建了一个状态为`Fulfilled`的`promise`对象**

#### reject

静态方法`reject`和`resolve`原理是一样的,所以可以直接参考上面的`resolve`方法.

```javascript
//源码
Promise$1.reject = reject$1;
function reject$1(reason) {
  /*jshint validthis:true */
  var Constructor = this;
  var promise = new Constructor(noop);
  reject(promise, reason);
  return promise;
}
```

#### catch

```javascript
//源码
Promise.prototype.catch = function _catch(onRejection) {
  return this.then(null, onRejection);
};
```

我们看到`catch`方法只接收一个参数`onRejection`,但需要注意的是内部调用`then(null, onRejection)`方法时第一个参数是`null`说明只有在`promise`对象的状态是`Rejected`情况下可以使用这种别名方式.

```javascript
// 示例一 常规
new ES6Promise((resolve, reject) => {
  reject(new Error('error'));
}).then(
  (v) => {
    console.log(v);
  },
  (e) => {
    console.log(e);
  }
);
// 示例二 别名方式
new ES6Promise((resolve, reject) => {
  reject(new Error('error'));
}).catch((e) => {
  console.log(e);
});
```

上面示例二直接使用`catch`方法,前提条件是已经知道`promise`对象的状态是`Rejected`,但我们在实际的开发中不知道状态的情况下该如何使用.

```javascript
// 示例三
new ES6Promise((resolve, reject) => {
  //使用setTimeout模拟请求
  setTimeout(() => {
    var s = new Date().getSeconds();
    s % 2 === 0 ? resolve({ name: 'zhangsan' }) : reject(new Error('无响应'));
  }, 5000);
}).then(
  (v) => {
    console.log(v);
  },
  (e) => {
    console.log(e);
  }
);
```

示例三通过判断时间秒数(0-59)的奇偶情况模拟请求有无数据.

- 偶数表示有数据,调用`resolve`函数改变状态为`Fulfilled`
- 奇数表示请求无响应,调用`reject`函数改变状态为`Rejected`

对于像示例三这种不知道状态的情况,显然是不适合直接使用`catch`方法的,下面示例四、示例五演示了这种情况.

```javascript
// 示例四
new ES6Promise((resolve, reject) => {
  //使用setTimeout模拟请求
  setTimeout(() => {
    var s = new Date().getSeconds();
    s % 2 === 0 ? resolve({ name: 'zhangsan' }) : reject(new Error('无响应'));
  }, 5000);
}).then(null, (e) => {
  console.log(e);
});

// 示例五 (示例四的别名写法)
new ES6Promise((resolve, reject) => {
  //使用setTimeout模拟请求
  setTimeout(() => {
    var s = new Date().getSeconds();
    s % 2 === 0 ? resolve({ name: 'zhangsan' }) : reject(new Error('无响应'));
  }, 5000);
}).catch((e) => {
  console.log(e);
});
```

可以通过示例四、示例五看出来 无论是`then`还是`catch`方法都是只处理了`Rejected`的状态,所以如果秒数返回偶数,调用`resolve`函数改变状态为`Fulfilled`则没有对应的回调函数做处理.

以上示例还是使用常规`then`的写法吧那`catch`适用什么场景呢我们接着看下面的示例.

```javascript
// 示例六
new ES6Promise((resolve, reject) => {
  //使用setTimeout模拟请求
  setTimeout(() => {
    resolve({ name: 'zhangsan' });
  }, 5000);
}).then(
  (v) => {
    console.log('开始处理数据....');
    throw new Error('数据处理过程发生错误...');
  },
  (e) => {
    console.log(e);
  }
);
```

示例六的场景想必大家也遇到过在对数据处理的过程中发生异常该如何处理,先回顾一下`then(onFulfillment, onRejection)`方法的使用方式.
接收 2 个参数

- `onFulfillment`回调函数处理`promise`对象状态为`Fulfilled`的情况
- `onRejection`回调函数是处理`promise`对象状态为`Rejected`的情况

这两个回调函数是平级,也就是说由于`promise`对象只会变化一次状态,所以 2 个回调函数只对同一个`promise`对象负责.
简单理解`onFulfillment`回调函数里发生翻天覆地的事情,`onRejection`也不会多管闲事(因为`promsie`对象已经选择了`onFulfillment`)
那怎么办出了问题总要有背锅的吧.让新人背吧.

```javascript
// 示例七
new ES6Promise((resolve, reject) => {
  //使用setTimeout模拟请求
  setTimeout(() => {
    resolve({ name: 'zhangsan' });
  }, 5000);
})
  .then(
    (v) => {
      console.log('开始处理数据....');
      throw new Error('数据处理过程发生错误...');
    },
    (e) => {
      console.log(e);
    }
  )
  .then(
    (v) => {
      console.log(v);
    },
    (e) => {
      console.log('上一个then甩出来什么锅都是我的', e);
    }
  );
```

如示例七所示由于`then`是可以链式调用所以把异常甩给下一任(甩给下一个`then`).至此应该明白`catch`的使用场景了吧,如果示例七还没看明白那就看示例八

```javascript
// 示例八
new ES6Promise((resolve, reject) => {
  //使用setTimeout模拟请求
  setTimeout(() => {
    resolve({ name: 'zhangsan' });
  }, 5000);
})
  .then(
    (v) => {
      console.log('开始处理数据....');
      throw new Error('数据处理过程发生错误...');
    },
    (e) => {
      console.log(e);
    }
  )
  .then(null, (e) => {
    console.log('上一个then甩出来什么锅都是我的', e);
  });
```

如果示例八还没看明白那就看示例九

```javascript
// 示例就 (示例八的别名)
new ES6Promise((resolve, reject) => {
  //使用setTimeout模拟请求
  setTimeout(() => {
    resolve({ name: 'zhangsan' });
  }, 5000);
})
  .then(
    (v) => {
      console.log('开始处理数据....');
      throw new Error('数据处理过程发生错误...');
    },
    (e) => {
      console.log(e);
    }
  )
  .catch((e) => {
    console.log('上一个then甩出来什么锅都是我的', e);
  });
```

#### race

```javascript
// 源码
function race(entries) {
  /*jshint validthis:true */
  var Constructor = this;

  if (!isArray(entries)) {
    return new Constructor(function (_, reject) {
      return reject(new TypeError('You must pass an array to race.'));
    });
  } else {
    return new Constructor(function (resolve, reject) {
      var length = entries.length;
      for (var i = 0; i < length; i++) {
        Constructor.resolve(entries[i]).then(resolve, reject);
      }
    });
  }
}
```

`race`静态方法与`all`静态方法使用方式一样,需要注意的是`race`静态方法内循环迭代的`promise`对象只要有一个状态发生变化`Fulfilled`或`Rejected`则会进行后续处理(调用父`promise`的`then`方法).
感兴趣的自己解析一下`race`源码吧.